Workbook

Sheet README
A1: VELOOP Rewards - Data Analyst Internship Task 01 - Analytics Workbook
A2: Prepared by Iqra Siddiqui (ID VLRINT202601918). Version 1.0, 7 Oct 2026.
A3: DATA AUTHENTICITY: all data referred to here is SIMULATED / FICTIONAL. No figure in this workbook is an actual VELOOP user, earning, withdrawal, revenue, retention or performance statistic. Proposed events, fields and KPIs are NOT claimed to exist in production.
A5: Item | B5: Count (live formula) | C5: Brief minimum
A6: Events in Event Plan | B6: =COUNTA('7 Event Plan (F)'!A4:A45) -> 42 | C6: 25
A7: Fields in Data Dictionary | B7: =COUNTA('10 Data Dictionary (G)'!B4:B109) -> 106 | C7: 75
A8: KPIs in KPI Catalogue | B8: =COUNTA('11 KPI Catalogue (I)'!A4:A57) -> 54 | C8: 30
A9: Analytics gaps | B9: =COUNTA('5 Analytics Gaps'!A4:A17) -> 14 | C9: 10
A10: Assumptions registered | B10: =COUNTA('2 Assumptions (S)'!A4:A33) -> 30 | C10: -
A11: Data-quality issues logged | B11: =COUNTA('16 DQ Audit (K)'!A4:A29) -> 26 | C11: -
A12: of which Critical | B12: =COUNTIF('16 DQ Audit (K)'!F4:F29,"Critical") -> 1 | C12: -
A13: of which High | B13: =COUNTIF('16 DQ Audit (K)'!F4:F29,"High") -> 9 | C13: -
A14: Dashboard visuals specified | B14: =COUNTA('18 Dashboard Spec (M)'!B4:B47) -> 44 | C14: -
A15: Backlog items | B15: =COUNTA('21 Backlog'!B4:B25) -> 22 | C15: -
A18: Deliverable index (workbook sheets)
A19: 03 Data Coverage Matrix | B19: 3 Product Area Map (A1), 4 Coverage Matrix (A4), 5 Analytics Gaps
A20: 04 User Analytics Specification | B20: 6 User Spec (B)
A21: 08 Event Tracking Plan | B21: 7 Event Plan (F), 8 Naming Standard
A22: 09 Data Dictionary | B22: 10 Data Dictionary (G)
A23: 11 KPI Catalogue | B23: 11 KPI Catalogue (I)
A24: 12 Simulated Data Profiling | B24: 12-15 (J1, J2, J3)
A25: 13 Data Quality Audit | B25: 16 DQ Audit (K), 17 DQ Controls (L)
A26: 14 Dashboard Blueprint (specs) | B26: 18 Dashboard Spec (M)
A27: 15 Developer Analytics Handoff | B27: 9 Dev Handoff (N)
A28: 18 Analytics Readiness Assessment | B28: 20 Readiness (R)
A29: 19 Assumption & Verification Register | B29: 1 Source Register, 2 Assumptions (S)
A30: 20 Implementation Backlog | B30: 21 Backlog
... A32: Deliverables 01, 02, 05, 06, 07, 10, 16, 17, 21 | B32: In VELOOP_Task01_Final_Report.docx

Sheet 1 Source Register
A1: Source & Verification Register (Brief section 6)
A2: SIMULATED DATA - NOT ACTUAL VELOOP DATA. Status legend: Confirmed / Proposed / To Be Verified. No proposed item is claimed to exist in production.
A3: Source ID | B3: Information | C3: Source | D3: Source Type | E3: Date Checked | F3: Status | G3: Notes / Limitation
A4: S001 | B4: VELOOP is a developing rewards & engagement ecosystem without enough production data for conventional performance analysis | C4: Data_Analyst_01.pdf §5, §35 | D4: Official (task brief) | E4: 2026-10-07 | F4: Confirmed | G4: Statement by the company; not independently verifiable by the analyst.
A5: S002 | B5: Relevant product areas: accounts, earning activities, VEs, XP, Gems, Tokens, Spins, daily rewards, streaks, tasks, missions, badges, levels, referrals, wallet, exchange, withdrawals, feature engagement, support/help, future features | C5: Data_Analyst_01.pdf §5 | D5: Official (task brief) | E5: 2026-10-07 | F5: Confirmed | G5: Confirmed only as a list of RELEVANT areas. Production implementation of each is To Be Verified.
A6: S003 | B6: Not every feature may be implemented or production-ready | C6: Data_Analyst_01.pdf §5 | D6: Official (task brief) | E6: 2026-10-07 | F6: Confirmed | G6: Drives the Confirmed / Proposed / To Be Verified labelling used in every deliverable.
A7: S004 | B7: Task 01 Users dataset: 1,000 clean rows, 1,008 audit rows, period 01 Apr 2026 - 15 Sep 2026, 27 columns (28 in audit incl. data_environment) | C7: VELoop_Rewards_Data_01.xlsx (README_Data_Status, Users_1000_Clean, Users_Messy_Audit) | D7: Simulated | E7: 2026-10-07 | F7: Confirmed | G7: Fictional. Never to be cited as actual VELOOP users. Use wording: "In the simulated dataset...".
A8: S005 | B8: Supplied Task 01 workbook contains the Users entity only; Task Activity, Rewards, Wallet, Withdrawals, Referrals and Feature Events sheets listed in brief §28 were not supplied | C8: VELoop_Rewards_Data_01.xlsx (README: "Standalone Users dataset for Task 01") | D8: Simulated | E8: 2026-10-07 | F8: Confirmed | G8: Limits Work Packages J2/J3. A supplementary dataset was used for relationship/KPI testing (S006). Request to the program team recorded as A003.
A9: S006 | B9: Supplementary behavioral dataset (Users 1,000; Sessions 7,913; Feature Events 35,704; Daily Activity 6,667; Task Activity 9,846; Milestones 4,799; Event audit 35,714) - labelled "Task 02" | C9: VELOOP_Simulated_User_Behavior_1000.xlsx (09_README_Status) | D9: Simulated | E9: 2026-10-07 | F9: Confirmed | G9: Used ONLY as a clearly labelled supplementary test bed. Its user_id values collide with S004 but describe different people (see DQ-014), so the two files are never joined.
A10: S007 | B10: 15 feature names appear in the supplementary dataset: Watch Ads, Missions, Streak Rewards, CAPTCHA, Tap & Earn, Mining Rewards, Referral, Daily Reward, Level System, Spin the Wheel, Wallet, Leaderboard, Badges, Exchange Center, Follow & Earn | C10: VELOOP_Simulated_User_Behavior_1000.xlsx (03_Feature_Events, 07_Feature_Usage) | D10: Simulated | E10: 2026-10-07 | F10: To Be Verified | G10: Names are used as a working feature list. Whether each exists in production is unverified (A006).
A11: S008 | B11: Supported withdrawal methods, minimum amounts, review rules | C11: Not supplied | D11: n/a | E11: 2026-10-07 | F11: To Be Verified | G11: Method is proposed as a field only; no methods are assumed (A010).
A12: S009 | B12: Definitions and conversion between VEs, XP, Gems, Tokens | C12: Data_Analyst_01.pdf §5 (names only) | D12: Official (task brief) | E12: 2026-10-07 | F12: To Be Verified | G12: Only the names are known. reward_unit is therefore designed as a controlled list to be filled by Product (A008).
A13: S010 | B13: External providers behind ads, surveys, offers, games, tracking | C13: Not supplied | D13: n/a | E13: 2026-10-07 | F13: To Be Verified | G13: Analytics designed to tolerate external-system outcomes (§C4) without naming providers (A012).
A14: S011 | B14: Session identifier exists in production events | C14: Data_Analyst_01.pdf §B1 (requested as requirement) | D14: Official (task brief) | E14: 2026-10-07 | F14: To Be Verified | G14: Proposed as an analytics field. Not assumed to exist (A004).
... A17: S014 | B17: Data authenticity and integrity rules (no fabricated stats, no credentials, no unnecessary personal data) | C17: Data_Analyst_01.pdf §2, §30, §34 | D17: Official (task brief) | E17: 2026-10-07 | F17: Confirmed | G17: Applied across all deliverables.

Sheet 2 Assumptions (S)
A1: Assumption & Verification Register (Work Package S)
A2: SIMULATED DATA - NOT ACTUAL VELOOP DATA. Status legend: Confirmed / Proposed / To Be Verified. No proposed item is claimed to exist in production.
A3: ID | B3: Unknown | C3: Why It Matters | D3: Source Checked | E3: Risk | F3: Verification Owner | G3: Status
A4: A001 | B4: Does the backend currently emit task completion events? | C4: Required for all task analytics and reward reconciliation | D4: Product brief; no engineering docs supplied | E4: High | F4: Engineering | G4: To Be Verified
A5: A002 | B5: Is there a stable, immutable user_id issued at registration (independent of email)? | C5: Cross-event joins and de-duplication depend on it | D5: Simulated Users data only | E5: Critical | F5: Engineering | G5: To Be Verified
A6: A003 | B6: Will the program team supply the missing Task Activity, Rewards, Wallet, Withdrawals, Referrals, Feature Events sheets? | C6: Needed to test relationships and KPIs required by J2/J3 on the intended dataset | D6: Data_01 README | E6: High | F6: Program team / Admin | G6: To Be Verified
A7: A004 | B7: Does production generate a session_id and where is a session closed? | C7: Session-level KPIs and funnels need it | D7: Brief §B1 | E7: High | F7: Engineering | G7: To Be Verified
A8: A005 | B8: Is event_id generated client-side or server-side, and is it idempotent on retry? | C8: Duplicate events inflate KPIs | D8: None | E8: Critical | F8: Engineering | G8: To Be Verified
A9: A006 | B9: Which of the 15 feature names actually exist in production today? | C9: Event plan and dashboards must not cover non-existent features | D9: Simulated feature list | E9: Medium | F9: Product | G9: To Be Verified
A10: A007 | B10: Is reward crediting synchronous with task completion or delayed by validation? | C10: Determines whether reward_pending is a real state | D10: None | E10: High | F10: Product / Engineering | G10: To Be Verified
A11: A008 | B11: What are the exact reward units (VE, XP, Gem, Token) and are there conversion rules? | C11: Amount fields need a unit; cross-unit totals are invalid without rules | D11: Brief names only | E11: High | F11: Product | G11: To Be Verified
A12: A009 | B12: Is there a single wallet ledger or one balance per currency? | C12: Defines the transaction model and balance reconciliation | D12: None | E12: Critical | F12: Engineering | G12: To Be Verified
A13: A010 | B13: Which withdrawal methods, minimums and review steps exist? | C13: Method distribution, processing-time and rejection KPIs depend on it | D13: None | E13: High | F13: Product / Operations | G13: To Be Verified
A14: A011 | B14: Is a status-change history stored for accounts (e.g. Active to Suspended)? | C14: Without history, activity before/after suspension cannot be separated | D14: Simulated Users has current status only | E14: High | F14: Engineering | G14: To Be Verified
... A33: A030 | B33: Is there an existing analytics tool or warehouse? | C33: Pipeline recommendation must fit current stack and cost | D33: None | E33: Medium | F33: Engineering | G33: To Be Verified

Sheet 3 Product Area Map (A1)
A1: A1 - Product Area Mapping
A2: SIMULATED DATA - NOT ACTUAL VELOOP DATA. Status legend: Confirmed / Proposed / To Be Verified. No proposed item is claimed to exist in production.
A3: Product Area | B3: Feature | C3: User Action | D3: System Outcome | E3: Data Required | F3: Business Question | G3: Status
A4: Account | B4: Registration | C4: User submits sign-up (web form or Google Sign-In) | D4: Account created; user_id issued | E4: user_id, registration_ts, account_created_via, acquisition_source, device, platform | F4: How many users join and from which channels? | G4: Proposed
A5: Account | B5: Email verification | C5: User confirms email | D5: Verification status updated | E5: user_id, verification_status, verified_ts | F5: What share of registrations verify and how fast? | G5: Proposed
A6: Account | B6: Login | C6: User signs in | D6: Session created | E6: user_id, session_id, login_ts, device, platform | F6: Who returns and how often? | G6: Proposed
A7: Account | B7: Logout | C7: User signs out | D7: Session closed | E7: user_id, session_id, logout_ts | F7: How long are sessions? | G7: Proposed
A8: Account | B8: Onboarding | C8: User starts/finishes onboarding | D8: Onboarding status updated | E8: user_id, onboarding_status, step, ts | F8: Where do new users drop off? | G8: Proposed
A9: Account | B9: Account status | C9: None (system or staff action) | D9: Status changed (Active/Inactive/Suspended/Pending Verification) | E9: user_id, old_status, new_status, reason_category, changed_by_type, ts | F9: How many accounts are suspended and why? | G9: Proposed
A10: Account | B10: Consent & marketing preference | C10: User accepts consent / toggles marketing opt-in | D10: Consent record stored | E10: user_id, consent_status, marketing_opt_in, ts | F10: Is consent captured and auditable? | G10: Proposed
A11: Tasks | B11: Task discovery | C11: User sees a task | D11: Task listed | E11: user_id, task_id, task_type, feature, ts | F11: Which tasks get attention? | G11: Proposed
A12: Tasks | B12: Task open | C12: User opens task detail | D12: None | E12: user_id, task_id, ts | F12: How many viewers open? | G12: Proposed
A13: Tasks | B13: Task start | C13: User starts the task | D13: Task attempt created | E13: user_id, task_id, task_activity_id, start_ts | F13: What is the start rate? | G13: Proposed
A14: Tasks | B14: Task completion | C14: User completes the action | D14: Completion validated (internal or external) | E14: user_id, task_id, task_activity_id, completion_ts, validation_status, reward_amount, reward_unit | F14: What share of starts complete validly? | G14: Proposed
... A34: Support | B34: Support request | C34: User creates ticket | D34: Ticket created | E34: ticket_id, user_id, issue_category | F34: What drives tickets? | G34: To Be Verified

Sheet 4 Coverage Matrix (A4)
A1: A4 - Data Coverage Matrix
A2: SIMULATED DATA - NOT ACTUAL VELOOP DATA. Status legend: Confirmed / Proposed / To Be Verified. No proposed item is claimed to exist in production.
A3: Product Area | B3: Feature | C3: User Action | D3: System Action | E3: Business Outcome | F3: Data Required | G3: Proposed Event | H3: Source | I3: Business Question | J3: Status | K3: Priority
A4: Account | B4: Registration | C4: User submits sign-up (web form or Google Sign-In) | D4: Account created; user_id issued | E4: New user exists | F4: user_id, registration_ts, account_created_via, acquisition_source, device, platform | G4: user_registered | H4: Backend | I4: How many users join and from which channels? | J4: Proposed | K4: Critical
A5: Account | B5: Email verification | C5: User confirms email | D5: Verification status updated | E5: Account becomes verified | F5: user_id, verification_status, verified_ts | G5: email_verified | H5: Backend | I5: What share of registrations verify and how fast? | J5: Proposed | K5: High
A6: Account | B6: Login | C6: User signs in | D6: Session created | E6: Returning visit | F6: user_id, session_id, login_ts, device, platform | G6: user_logged_in | H6: Backend | I6: Who returns and how often? | J6: Proposed | K6: Critical
A7: Account | B7: Logout | C7: User signs out | D7: Session closed | E7: Session end captured | F7: user_id, session_id, logout_ts | G7: user_logged_out | H7: Frontend | I7: How long are sessions? | J7: Proposed | K7: Low
A8: Account | B8: Onboarding | C8: User starts/finishes onboarding | D8: Onboarding status updated | E8: Activated user | F8: user_id, onboarding_status, step, ts | G8: onboarding_started / onboarding_completed | H8: Frontend + Backend | I8: Where do new users drop off? | J8: Proposed | K8: High
A9: Account | B9: Account status | C9: None (system or staff action) | D9: Status changed (Active/Inactive/Suspended/Pending Verification) | E9: Eligibility to earn/withdraw changes | F9: user_id, old_status, new_status, reason_category, changed_by_type, ts | G9: account_status_changed | H9: Backend | I9: How many accounts are suspended and why? | J9: Proposed | K9: High
A10: Account | B10: Consent & marketing preference | C10: User accepts consent / toggles marketing opt-in | D10: Consent record stored | E10: Compliance evidence | F10: user_id, consent_status, marketing_opt_in, ts | G10: consent_updated | H10: Backend | I10: Is consent captured and auditable? | J10: Proposed | K10: Medium
A11: Tasks | B11: Task discovery | C11: User sees a task | D11: Task listed | E11: Task exposure | F11: user_id, task_id, task_type, feature, ts | G11: task_viewed | H11: Frontend | I11: Which tasks get attention? | J11: Proposed | K11: High
A12: Tasks | B12: Task open | C12: User opens task detail | D12: None | E12: Interest | F12: user_id, task_id, ts | G12: task_opened | H12: Frontend | I12: How many viewers open? | J12: Proposed | K12: Medium
A13: Tasks | B13: Task start | C13: User starts the task | D13: Task attempt created | E13: Attempt | F13: user_id, task_id, task_activity_id, start_ts | G13: task_started | H13: Backend | I13: What is the start rate? | J13: Proposed | K13: Critical
A14: Tasks | B14: Task completion | C14: User completes the action | D14: Completion validated (internal or external) | E14: Valid completion | F14: user_id, task_id, task_activity_id, completion_ts, validation_status, reward_amount, reward_unit | G14: task_completed | H14: Backend | I14: What share of starts complete validly? | J14: Proposed | K14: Critical
... A34: Support | B34: Support request | C34: User creates ticket | D34: Ticket created | E34: Support load | F34: ticket_id, user_id, issue_category | G34: support_ticket_created | H34: Support tool | I34: What drives tickets? | J34: To Be Verified | K34: Medium

Sheet 5 Analytics Gaps
A1: Analytics Gaps (10+ required, 14 identified)
A2: SIMULATED DATA - NOT ACTUAL VELOOP DATA. Status legend: Confirmed / Proposed / To Be Verified. No proposed item is claimed to exist in production.
A3: Gap ID | B3: Analytics Gap | C3: Affects | D3: Priority | E3: Reason for Priority
A4: AG01 | B4: No verified stable event_id and no idempotency design | C4: All event KPIs | D4: Critical | E4: Without a unique event_id, duplicates cannot be removed; the supplementary audit file contains 10 duplicated event rows.
A5: AG02 | B5: Wallet transaction_id and ledger design unverified | C5: Wallet, rewards, withdrawals | D5: Critical | E5: Without a stable transaction ID reliable deduplication and balance reconciliation cannot be guaranteed.
A6: AG03 | B6: No referrer-to-referred link in supplied Users data (only "Friend/Family" label and one code per user) | C6: Referral KPIs | D6: Critical | E6: Referral conversion cannot be computed without referrer and referred user IDs.
A7: AG04 | B7: No account status-change history | C7: User lifecycle, fraud/suspension reporting | D7: High | E7: Current status alone cannot show whether activity occurred before or after suspension (25 simulated suspended users show 30-day activity).
A8: AG05 | B8: Reward credited vs activity occurred not separable in Task 01 data | C8: Reward KPIs | D8: Critical | E8: No Rewards sheet was supplied; reward value cannot be reconciled with completions.
A9: AG06 | B9: Withdrawal lifecycle timestamps not available | C9: Withdrawal KPIs | D9: Critical | E9: Processing time, pending queue and completion rate need requested/processing/final timestamps.
A10: AG07 | B10: Session ID not verified in production | C10: Session and funnel analysis | D10: High | E10: Funnel steps cannot be tied to one visit without a session identifier.
A11: AG08 | B11: Failure classification does not exist (only proposed) | C11: Task failure analysis | D11: High | E11: Failure reasons need a controlled list agreed with Engineering.
A12: AG09 | B12: Derived-field definitions undocumented (active flags, days since registration) | C12: User KPIs | D12: Medium | E12: Flags could not be reproduced for 8-9 users; KPI definitions would drift.
A13: AG10 | B13: Timezone and timestamp standard unknown | C13: Daily KPIs | D13: High | E13: Mixed zones shift day boundaries; malformed dates exist in the audit sheet.
A14: AG11 | B14: No event for onboarding milestones beyond three status values | C14: Onboarding funnel | D14: Medium | E14: Drop-off location cannot be found.
... A17: AG14 | B17: Consent history not stored (current flag only) | C17: Privacy / compliance reporting | D17: Medium | E17: Audit of consent timing impossible.

Sheet 6 User Spec (B)
A1: B2 - User Analytics Specification
A2: SIMULATED DATA - NOT ACTUAL VELOOP DATA. Status legend: Confirmed / Proposed / To Be Verified. No proposed item is claimed to exist in production.
A3: Field | B3: Type | C3: Required? | D3: Purpose | E3: Source | F3: Validation | G3: Status
A4: user_id | B4: String | C4: Yes | D4: Stable join key | E4: Simulated dataset (Data_01) | F4: Unique; not null; immutable | G4: Confirmed (simulated structure)
A5: full_name | B5: String | C5: No - excluded from analytics layer | D5: Not required for any KPI; personal data (brief section 9: no unnecessary personal information) | E5: Simulated dataset (Data_01) | F5: Exclude, or store a one-way hash of email for de-duplication only | G5: Proposed exclusion
A6: email | B6: String | C6: No - excluded from analytics layer | D6: Not required for any KPI; personal data (brief section 9: no unnecessary personal information) | E6: Simulated dataset (Data_01) | F6: Exclude, or store a one-way hash of email for de-duplication only | G6: Proposed exclusion
A7: age | B7: Integer | C7: No | D7: Optional segmentation | E7: Simulated dataset (Data_01) | F7: >=18 | G7: Confirmed (simulated structure)
A8: gender | B8: Category | C8: No | D8: Optional segmentation | E8: Simulated dataset (Data_01) | F8: Controlled list | G8: Confirmed (simulated structure)
A9: state | B9: Category | C9: No | D9: Geography | E9: Simulated dataset (Data_01) | F9: City-state consistency | G9: Confirmed (simulated structure)
A10: city | B10: Category | C10: No | D10: Geography (optional) | E10: Simulated dataset (Data_01) | F10: City belongs to state | G10: Confirmed (simulated structure)
A11: registration_datetime | B11: Datetime | C11: Yes | D11: Cohorts and registration KPIs | E11: Simulated dataset (Data_01) | F11: Valid ISO datetime; zone documented | G11: Confirmed (simulated structure)
A12: acquisition_source | B12: Category | C12: Yes | D12: Channel analysis | E12: Simulated dataset (Data_01) | F12: Controlled list | G12: Confirmed (simulated structure)
A13: referral_source_detail | B13: Category | C13: Conditional | D13: Referral detail | E13: Simulated dataset (Data_01) | F13: Required only if acquisition_source = Referral | G13: Confirmed (simulated structure)
A14: primary_device | B14: Category | C14: Yes | D14: Platform priorities | E14: Simulated dataset (Data_01) | F14: Controlled list | G14: Confirmed (simulated structure)
... A30: country | B30: Category | C30: Yes | D30: Geography | E30: Simulated dataset (Data_01) | F30: Controlled list | G30: Confirmed (simulated structure)
A34: B1 - Identifier Requirements
A35: Identifier | B35: Definition | C35: Why Needed | D35: Rule
A36: user_id | B36: Stable, immutable, non-personal identifier of one account | C36: Joins every entity; must not be email or name | D36: Unique per account; never reused
A37: event_id | B37: Unique id of one recorded event (UUID) | C37: Detect and remove duplicate/replayed events | D37: Generated once per event; idempotent on retry
A38: session_id | B38: Groups events of one visit | C38: Funnels, session length, entry/exit analysis (existence unverified - A004) | D38: Created at login; closed on logout/timeout
A39: transaction_id | B39: Unique id of one wallet ledger entry | C39: Reconciliation, de-duplication, reversal linking (A009) | D39: Immutable; reversals reference original
A40: task_activity_id | B40: One attempt at a task | C40: Task funnel; idempotency key for task_completed | D40: One per attempt
A41: reward_id | B41: One reward record | C41: Separates reward credited from activity occurred | D41: One per reward
A42: withdrawal_id | B42: One payout request | C42: Withdrawal lifecycle | D42: One per request
A43: referral_id | B43: One referral relationship | C43: Referral funnel | D43: One per referrer-referred pair
A46: Lifecycle requirements
A47: Registration | B47: user_id, registration timestamp, registration method, acquisition source, device/platform; referral code used if any
A48: Login | B48: login event, timestamp, session identifier (if verified), device/platform
A49: Onboarding | B49: started, completed and (once defined, A026) important milestones
A50: Account lifecycle | B50: account created, status, status changes with timestamp and category, last activity, lifecycle timestamps

Sheet 7 Event Plan (F)
A1: F - Production Event Tracking Plan (42 proposed events)
A2: SIMULATED DATA - NOT ACTUAL VELOOP DATA. Status legend: Confirmed / Proposed / To Be Verified. No proposed item is claimed to exist in production.
A3: Event Name | B3: Domain | C3: Feature | D3: Event Class | E3: Trigger | F3: Definition | G3: User ID | H3: Event ID | I3: Timestamp | J3: Status Values | K3: Required Properties (type) | L3: Optional Properties (type) | M3: Validation | N3: Source | O3: Business Purpose | P3: KPI Dependency | Q3: Implementation Status | R3: Priority | S3: Observed in Simulated Data As
A4: user_registered | B4: account | C4: registration | D4: User Event | E4: Account record is successfully created | F4: A new account exists with a permanent user_id | G4: Required: user_id (string) | H4: Required: event_id (string, UUID) | I4: Required: event_ts (UTC ISO-8601) | J4: n/a | K4: registration_method (enum: web_form, google_sign_in), acquisition_source (enum), device_type (enum), platform (enum) | L4: referral_code_used (string), campaign_ref (string) | M4: user_id unique; registration_method in list; one event per user_id | N4: Backend | O4: Count new users and acquisition mix | P4: K-U01, K-U02, K-U10 | Q4: Proposed | R4: Critical | S4: Users.registration_datetime (no event stream)
A5: email_verified | B5: account | C5: verification | D5: User Event | E5: User confirms email successfully | F5: Email verification status changes to Verified | G5: Required: user_id (string) | H5: Required: event_id (string, UUID) | I5: Required: event_ts (UTC ISO-8601) | J5: n/a | K5: verification_method (enum) | L5: seconds_since_registration (int) | M5: one per user_id; after user_registered | N5: Backend | O5: Measure verification rate and speed | P5: K-U05 | Q5: Proposed | R5: High | S5: -
A6: user_logged_in | B6: account | C6: login | D6: User Event | E6: Authenticated session is created | F6: User signs in | G6: Required: user_id (string) | H6: Required: event_id (string, UUID) | I6: Required: event_ts (UTC ISO-8601) | J6: n/a | K6: session_id (string), device_type (enum), platform (enum) | L6: login_method (enum) | M6: session_id unique per login; user must exist | N6: Backend | O6: Returning-user and active-user KPIs | P6: K-U03, K-U04, K-U06 | Q6: Proposed | R6: Critical | S6: -
A7: user_logged_out | B7: account | C7: login | D7: User Event | E7: User explicitly signs out | F7: Session closed by user | G7: Required: user_id (string) | H7: Required: event_id (string, UUID) | I7: Required: event_ts (UTC ISO-8601) | J7: n/a | K7: session_id (string) | L7: - | M7: session_id must match an open session; not emitted on timeout | N7: Frontend | O7: Session length where explicit | P7: K-E09 | Q7: Proposed | R7: Low | S7: -
A8: onboarding_started | B8: account | C8: onboarding | D8: User Event | E8: First onboarding screen shown | F8: User begins onboarding | G8: Required: user_id (string) | H8: Required: event_id (string, UUID) | I8: Required: event_ts (UTC ISO-8601) | J8: n/a | K8: session_id (string) | L8: - | M8: one per user_id | N8: Frontend | O8: Onboarding funnel entry | P8: K-U07 | Q8: Proposed | R8: High | S8: -
A9: onboarding_completed | B9: account | C9: onboarding | D9: User Event | E9: Final required onboarding step done | F9: User finished onboarding | G9: Required: user_id (string) | H9: Required: event_id (string, UUID) | I9: Required: event_ts (UTC ISO-8601) | J9: n/a | K9: session_id (string), steps_completed (int) | L9: duration_seconds (int) | M9: after onboarding_started; one per user_id | N9: Frontend | O9: Activation measure | P9: K-U07 | Q9: Proposed | R9: High | S9: -
A10: account_status_changed | B10: account | C10: account_status | D10: System Event | E10: Account status value is modified | F10: Records old and new account status | G10: Required: user_id (string) | H10: Required: event_id (string, UUID) | I10: Required: event_ts (UTC ISO-8601) | J10: n/a | K10: old_status (enum), new_status (enum), change_reason_category (enum), changed_by_type (enum: system, staff, user) | L10: change_reference (string) | M10: old_status != new_status; values in approved list | N10: Backend | O10: Lifecycle and suspension reporting | P10: K-U08, K-U09 | Q10: Proposed | R10: High | S10: -
A11: consent_updated | B11: account | C11: consent | D11: System Event | E11: Consent or marketing preference saved | F11: Consent state changed | G11: Required: user_id (string) | H11: Required: event_id (string, UUID) | I11: Required: event_ts (UTC ISO-8601) | J11: n/a | K11: consent_status (enum), marketing_opt_in (bool) | L11: consent_version (string) | M11: values in list | N11: Backend | O11: Compliance evidence | P11: K-U11 | Q11: Proposed | R11: Medium | S11: -
A12: task_viewed | B12: tasks | C12: task_catalog | D12: User Event | E12: Task card is shown on screen | F12: User was shown a task | G12: Required: user_id (string) | H12: Required: event_id (string, UUID) | I12: Required: event_ts (UTC ISO-8601) | J12: n/a | K12: task_id (string), task_type (enum), feature (enum), session_id (string) | L12: position_in_list (int) | M12: task_id exists in task catalog | N12: Frontend | O12: Funnel top | P12: K-E02 | Q12: Proposed | R12: High | S12: tasks.task_viewed_at
A13: task_opened | B13: tasks | C13: task_catalog | D13: User Event | E13: Task details opened | F13: User opened a task | G13: Required: user_id (string) | H13: Required: event_id (string, UUID) | I13: Required: event_ts (UTC ISO-8601) | J13: n/a | K13: task_id (string), task_type (enum), session_id (string) | L13: - | M13: after task_viewed (same session preferred) | N13: Frontend | O13: Interest | P13: K-E02 | Q13: Proposed | R13: Medium | S13: -
A14: task_started | B14: tasks | C14: task_catalog | D14: User Event | E14: Task attempt created | F14: User began an attempt | G14: Required: user_id (string) | H14: Required: event_id (string, UUID) | I14: Required: event_ts (UTC ISO-8601) | J14: n/a | K14: task_activity_id (string), task_id (string), task_type (enum), feature (enum), session_id (string) | L14: provider_ref (string) | M14: one task_activity_id per attempt | N14: Backend | O14: Starts and completion rate denominator | P14: K-E01, K-E03 | Q14: Proposed | R14: Critical | S14: tasks.task_started_at
... A45: support_ticket_created | B45: support | C45: support | D45: User Event | E45: Ticket created in support tool | F45: Support request raised | G45: Required: user_id (string) | H45: Required: event_id (string, UUID) | I45: Required: event_ts (UTC ISO-8601) | J45: n/a | K45: ticket_id (string), issue_category (enum) | L45: related_feature (enum) | M45: ticket_id unique | N45: Support tool | O45: Support load | P45: K-S01 | Q45: Proposed | R45: Medium | S45: -

Sheet 8 Naming Standard
A1: Event Naming Standard
A2: SIMULATED DATA - NOT ACTUAL VELOOP DATA. Status legend: Confirmed / Proposed / To Be Verified. No proposed item is claimed to exist in production.
A3: Item | B3: Standard
A4: Convention | B4: object_action, snake_case, lower case, past-tense verb (user_registered, task_completed)
A5: Why | B5: Matches the brief minimum events; short; sorts by object so related events group together; the feature goes in a property (feature), not in the name, which avoids a name explosion
A6: Verbs | B6: registered, verified, logged_in, logged_out, started, completed, failed, abandoned, viewed, opened, credited, reversed, corrected, claimed, earned, requested, rejected, created, updated, changed, increased
A7: Rule 1 | B7: An event name is emitted only after the state is true (completed means validated). Intent is a separate event (started/requested).
A8: Rule 2 | B8: One event, one meaning. Renames are never silent (see Change Log process).
A9: Rule 3 | B9: Properties use snake_case; enums are lower case; amounts are decimal with a separate unit field; timestamps UTC ISO-8601.
A10: Rule 4 | B10: No personal data (name, email, free text) inside event properties.
A11: Mapping note | B11: The supplementary simulated dataset uses names such as mission_viewed, ad_started, level_up, streak_claimed. Column S of the Event Plan maps proposed names to those observed; they are not assumed to be production names.

Sheet 9 Dev Handoff (N)
A1: N - Developer Analytics Handoff (14 critical events, one row per payload field)
A2: SIMULATED DATA - NOT ACTUAL VELOOP DATA. Status legend: Confirmed / Proposed / To Be Verified. No proposed item is claimed to exist in production.
A3: Requirement ID | B3: Event | C3: Trigger | D3: Payload Field | E3: Data Type | F3: Required | G3: Validation | H3: Deduplication | I3: Timestamp | J3: Source | K3: Why Needed | L3: KPI Dependency | M3: Acceptance Test | N3: Priority
A4: REQ-001 | B4: user_registered | C4: Account record is successfully created | D4: user_id | E4: string | F4: Yes | G4: Not null; type-valid | H4: unique on user_id | I4: UTC, server-generated at the time the state is committed | J4: Backend | K4: Count new users and acquisition mix | L4: K-U01, K-U02, K-U10 | M4: When a new account is created, exactly one user_registered event with a new user_id is recorded; repeat submission of the same form creates no second event. | N4: Critical
A5: REQ-001 | B5: user_registered | C5: Account record is successfully created | D5: event_id | E5: string, UUID | F5: Yes | G5: Not null; type-valid | H5: unique on user_id | I5: UTC, server-generated at the time the state is committed | J5: Backend | K5: Count new users and acquisition mix | L5: K-U01, K-U02, K-U10 | M5: When a new account is created, exactly one user_registered event with a new user_id is recorded; repeat submission of the same form creates no second event. | N5: Critical
A6: REQ-001 | B6: user_registered | C6: Account record is successfully created | D6: event_ts | E6: UTC ISO-8601 | F6: Yes | G6: Not null; type-valid | H6: unique on user_id | I6: UTC, server-generated at the time the state is committed | J6: Backend | K6: Count new users and acquisition mix | L6: K-U01, K-U02, K-U10 | M6: When a new account is created, exactly one user_registered event with a new user_id is recorded; repeat submission of the same form creates no second event. | N6: Critical
A7: REQ-001 | B7: user_registered | C7: Account record is successfully created | D7: registration_method | E7: enum: web_form, google_sign_in | F7: Yes | G7: Not null; type-valid | H7: unique on user_id | I7: UTC, server-generated at the time the state is committed | J7: Backend | K7: Count new users and acquisition mix | L7: K-U01, K-U02, K-U10 | M7: When a new account is created, exactly one user_registered event with a new user_id is recorded; repeat submission of the same form creates no second event. | N7: Critical
A8: REQ-001 | B8: user_registered | C8: Account record is successfully created | D8: acquisition_source | E8: enum | F8: Yes | G8: Not null; type-valid | H8: unique on user_id | I8: UTC, server-generated at the time the state is committed | J8: Backend | K8: Count new users and acquisition mix | L8: K-U01, K-U02, K-U10 | M8: When a new account is created, exactly one user_registered event with a new user_id is recorded; repeat submission of the same form creates no second event. | N8: Critical
A9: REQ-001 | B9: user_registered | C9: Account record is successfully created | D9: device_type | E9: enum | F9: Yes | G9: Not null; type-valid | H9: unique on user_id | I9: UTC, server-generated at the time the state is committed | J9: Backend | K9: Count new users and acquisition mix | L9: K-U01, K-U02, K-U10 | M9: When a new account is created, exactly one user_registered event with a new user_id is recorded; repeat submission of the same form creates no second event. | N9: Critical
A10: REQ-001 | B10: user_registered | C10: Account record is successfully created | D10: platform | E10: enum | F10: Yes | G10: Not null; type-valid | H10: unique on user_id | I10: UTC, server-generated at the time the state is committed | J10: Backend | K10: Count new users and acquisition mix | L10: K-U01, K-U02, K-U10 | M10: When a new account is created, exactly one user_registered event with a new user_id is recorded; repeat submission of the same form creates no second event. | N10: Critical
A11: REQ-002 | B11: user_logged_in | C11: Authenticated session is created | D11: user_id | E11: string | F11: Yes | G11: Not null; type-valid | H11: unique on (user_id, session_id) | I11: UTC, server-generated at the time the state is committed | J11: Backend | K11: Returning-user and active-user KPIs | L11: K-U03, K-U04, K-U06 | M11: Each successful authentication produces one event carrying a session_id; a refresh without re-authentication produces none. | N11: Critical
A12: REQ-002 | B12: user_logged_in | C12: Authenticated session is created | D12: event_id | E12: string, UUID | F12: Yes | G12: Not null; type-valid | H12: unique on (user_id, session_id) | I12: UTC, server-generated at the time the state is committed | J12: Backend | K12: Returning-user and active-user KPIs | L12: K-U03, K-U04, K-U06 | M12: Each successful authentication produces one event carrying a session_id; a refresh without re-authentication produces none. | N12: Critical
A13: REQ-002 | B13: user_logged_in | C13: Authenticated session is created | D13: event_ts | E13: UTC ISO-8601 | F13: Yes | G13: Not null; type-valid | H13: unique on (user_id, session_id) | I13: UTC, server-generated at the time the state is committed | J13: Backend | K13: Returning-user and active-user KPIs | L13: K-U03, K-U04, K-U06 | M13: Each successful authentication produces one event carrying a session_id; a refresh without re-authentication produces none. | N13: Critical
A14: REQ-002 | B14: user_logged_in | C14: Authenticated session is created | D14: session_id | E14: string | F14: Yes | G14: Not null; type-valid | H14: unique on (user_id, session_id) | I14: UTC, server-generated at the time the state is committed | J14: Backend | K14: Returning-user and active-user KPIs | L14: K-U03, K-U04, K-U06 | M14: Each successful authentication produces one event carrying a session_id; a refresh without re-authentication produces none. | N14: Critical
... A111: REQ-014 | B111: withdrawal_rejected | C111: Request refused | D111: reason_category | E111: enum | F111: Yes | G111: Not null; type-valid | H111: unique on withdrawal_id + terminal status | I111: UTC, server-generated at the time the state is committed | J111: Backend | K111: Rejection reasons | L111: K-D04 | M111: Rejection records one event with a reason_category from the approved list and no completion event. | N111: High

Sheet 10 Data Dictionary (G)
A1: G - VELOOP Data Dictionary (106 fields)
A2: SIMULATED DATA - NOT ACTUAL VELOOP DATA. Status legend: Confirmed / Proposed / To Be Verified. No proposed item is claimed to exist in production.
A3: Entity | B3: Field Name | C3: Data Type | D3: Definition | E3: Example | F3: Required | G3: Allowed Values | H3: Validation | I3: Source | J3: Sensitivity | K3: Analytical Use | L3: Status
A4: Users | B4: user_id | C4: String | D4: Stable unique user identifier | E4: VLUSR000001 | F4: Yes | G4: VLUSR + 6 digits | H4: Unique; not null; immutable | I4: Simulated dataset (Data_01) | J4: Internal | K4: Primary join key | L4: Confirmed (simulated structure)
A5: Users | B5: full_name | C5: String | D5: Display name in simulated data (not needed in analytics layer) | E5: (simulated) | F5: No | G5: - | H5: Not unique (596 repeated names in sample); exclude from analytics layer | I5: Simulated dataset (Data_01) | J5: Restricted | K5: None - recommend exclusion | L5: Confirmed (simulated structure)
A6: Users | B6: email | C6: String | D6: Email address (not needed in analytics layer) | E6: (simulated) | F6: No | G6: - | H6: Valid format; unique; replace with hashed value if needed | I6: Simulated dataset (Data_01) | J6: Restricted | K6: De-duplication only (hashed) | L6: Confirmed (simulated structure)
A7: Users | B7: age | C7: Integer | D7: Age in years | E7: 28 | F7: No | G7: 18-38 in sample | H7: >=18 | I7: Simulated dataset (Data_01) | J7: Restricted | K7: Demographic segmentation (optional) | L7: Confirmed (simulated structure)
A8: Users | B8: gender | C8: Category | D8: Self-declared gender | E8: Prefer not to say | F8: No | G8: Male, Female, Prefer not to say | H8: Controlled list | I8: Simulated dataset (Data_01) | J8: Restricted | K8: Optional segmentation | L8: Confirmed (simulated structure)
A9: Users | B9: state | C9: Category | D9: Indian state | E9: Odisha | F9: No | G9: Controlled list | H9: City-state consistency | I9: Simulated dataset (Data_01) | J9: Internal | K9: Geographic distribution | L9: Confirmed (simulated structure)
A10: Users | B10: city | C10: Category | D10: City | E10: Bhubaneswar | F10: No | G10: Controlled list | H10: City belongs to state | I10: Simulated dataset (Data_01) | J10: Internal | K10: Geographic distribution | L10: Confirmed (simulated structure)
A11: Users | B11: registration_datetime | C11: Datetime | D11: Account creation timestamp | E11: 2026-06-10 07:14:00 | F11: Yes | G11: - | H11: Valid ISO datetime; zone documented | I11: Simulated dataset (Data_01) | J11: Internal | K11: Cohorts, registrations | L11: Confirmed (simulated structure)
A12: Users | B12: acquisition_source | C12: Category | D12: Channel through which the user arrived | E12: Organic Search | F12: Yes | G12: Organic Search, Direct, Social Media, Referral, WhatsApp, Telegram, Other | H12: Controlled list | I12: Simulated dataset (Data_01) | J12: Internal | K12: Acquisition analysis | L12: Confirmed (simulated structure)
A13: Users | B13: referral_source_detail | C13: Category | D13: Detail when source = Referral | E13: Friend/Family | F13: Conditional | G13: Friend/Family | H13: Required only if acquisition_source = Referral | I13: Simulated dataset (Data_01) | J13: Internal | K13: Referral analysis | L13: Confirmed (simulated structure)
A14: Users | B14: primary_device | C14: Category | D14: Main device OS family | E14: Android | F14: Yes | G14: Android, iOS, Windows, macOS | H14: Controlled list | I14: Simulated dataset (Data_01) | J14: Internal | K14: Device mix | L14: Confirmed (simulated structure)
... A109: Feature Events | B109: sequence_number | C109: Integer | D109: Order inside session | E109: 3 | F109: No | G109: >=1 | H109: Unique within session | I109: Simulated dataset (Data_01) (supplementary only) | J109: Internal | K109: Sequencing | L109: Confirmed (simulated structure)

Sheet 11 KPI Catalogue (I)
A1: I - KPI Catalogue (54 KPIs) - definitions only; no company targets
A2: SIMULATED DATA - NOT ACTUAL VELOOP DATA. Status legend: Confirmed / Proposed / To Be Verified. No proposed item is claimed to exist in production.
A3: KPI ID | B3: Area | C3: KPI Name | D3: Definition | E3: Formula | F3: Required Fields | G3: Data Source | H3: Frequency | I3: Stakeholder | J3: Business Purpose | K3: Interpretation | L3: Limitation | M3: Status | N3: Testable on supplied simulated data?
A4: K-U01 | B4: User | C4: New registrations | D4: Distinct users whose account was created in the period | E4: COUNT(DISTINCT user_id) WHERE registration_ts in period | F4: user_id, registration_ts | G4: Users / user_registered | H4: Daily | I4: Product, Growth | J4: Measure intake | K4: Rising count = more sign-ups; interpret with source mix | L4: Counts accounts, not unique people; duplicates must be removed first | M4: Proposed | N4: Yes - Task 01 Users sheet
A5: K-U02 | B5: User | C5: Registrations by acquisition source | D5: New registrations split by acquisition_source | E5: registrations per source / total registrations | F5: user_id, acquisition_source, registration_ts | G5: Users | H5: Weekly | I5: Growth | J5: Channel mix | K5: Shows dependence on channels | L5: Source taxonomy to be agreed; "Other" hides detail | M5: Proposed | N5: Yes - Task 01 Users sheet
A6: K-U03 | B6: User | C6: Daily Active Users (DAU) | D6: Unique users generating a qualifying activity event within a calendar day | E6: COUNT(DISTINCT user_id) with >=1 qualifying event on date D | F6: user_id, event_ts, event_name | G6: Event stream | H6: Daily | I6: Product, Management | J6: Core activity | K6: Compare with MAU for stickiness | L6: Depends on the list of qualifying events (A017) and time zone (A015) | M6: Proposed | N6: Yes - supplementary dataset only
A7: K-U04 | B7: User | C7: Monthly Active Users (MAU) | D7: Unique users with a qualifying event in a rolling 30 days | E7: COUNT(DISTINCT user_id) WHERE event_ts in last 30 days | F7: user_id, event_ts | G7: Event stream | H7: Daily | I7: Management | J7: Scale of use | K7: Context for DAU/MAU | L7: Same as DAU | M7: Proposed | N7: Yes - supplementary dataset only
A8: K-U05 | B8: User | C8: Email verification rate | D8: Share of registered users with verified email | E8: verified users / registered users | F8: user_id, email_verification_status | G8: Users | H8: Weekly | I8: Product | J8: Funnel health | K8: Low rate suggests friction | L8: Current-state flag only; no verification timestamp | M8: Proposed | N8: Yes - Task 01 Users sheet
A9: K-U06 | B9: User | C9: Returning users | D9: Users with qualifying activity in the period who registered before the period start | E9: COUNT(DISTINCT user_id) active in period AND registration_ts < period start | F9: user_id, registration_ts, event_ts | G9: Users + events | H9: Weekly | I9: Product | J9: Retention proxy | K9: Higher is healthier | L9: Not a cohort retention curve | M9: Proposed | N9: Yes - supplementary dataset only
A10: K-U07 | B10: User | C10: Onboarding completion rate | D10: Share of registered users with onboarding Completed | E10: users with onboarding_status = Completed / registered users | F10: user_id, onboarding_status | G10: Users | H10: Weekly | I10: Product | J10: Activation | K10: Drop shows onboarding friction | L10: Three states only; no step detail | M10: Proposed | N10: Yes - Task 01 Users sheet
A11: K-U08 | B11: User | C11: Suspended account share | D11: Share of accounts currently Suspended | E11: Suspended / all accounts | F11: user_id, account_status | G11: Users | H11: Weekly | I11: Operations | J11: Risk monitoring | K11: Rise warrants review | L11: No reason or timing without status history | M11: Proposed | N11: Yes - Task 01 Users sheet
A12: K-U09 | B12: User | C12: Status transitions | D12: Count of account_status_changed events by old to new status | E12: COUNT(*) GROUP BY old_status, new_status | F12: status history | G12: Account Status History | H12: Weekly | I12: Operations | J12: Lifecycle flow | K12: Shows churn and suspension flow | L12: Table does not exist yet (A011) | M12: Proposed | N12: No - source table not supplied
A13: K-U10 | B13: User | C13: Registrations by device and platform | D13: New registrations by primary_device and platform | E13: registrations per device / total | F13: user_id, primary_device, platform | G13: Users | H13: Weekly | I13: Product, Engineering | J13: Prioritise platforms | K13: Android-heavy mix would favour mobile-first design | L13: One platform value in sample | M13: Proposed | N13: Yes - Task 01 Users sheet
A14: K-U11 | B14: User | C14: Consent acceptance rate | D14: Share of users whose consent_status = Accepted | E14: Accepted / all users | F14: user_id, consent_status | G14: Users | H14: Weekly | I14: Legal, Product | J14: Compliance | K14: Pending users may be restricted | L14: No consent timestamp | M14: Proposed | N14: Yes - Task 01 Users sheet
... A57: K-S03 | B57: Support | C57: Issue categories | D57: Tickets by issue_category | E57: COUNT GROUP BY category | F57: issue_category | G57: Support tool | H57: Weekly | I57: Operations, Product | J57: Pain points | K57: - | L57: Category list to be agreed | M57: Proposed | N57: No - source table not supplied

Sheet 12 Profile Summary (J1)
A1: J1 - Dataset Profiling (T01 = Task 01 file; SUP = supplementary file; both SIMULATED)
A2: SIMULATED DATA - NOT ACTUAL VELOOP DATA. Status legend: Confirmed / Proposed / To Be Verified. No proposed item is claimed to exist in production.
A3: Dataset | B3: Records | C3: Columns | D3: Date Range | E3: ID Field | F3: Unique IDs | G3: Duplicate IDs | H3: Fully Duplicate Rows | I3: Missing Cells | J3: Columns With Missing | K3: Notes
A4: T01 Users_1000_Clean | B4: 1000 | C4: 27 | D4: 2026-04-01 02:10:00 to 2026-09-15 19:47:00 | E4: user_id | F4: 1000 | G4: 0 | H4: 0 | I4: 953 | J4: 2 | K4: Nulls: referral_source_detail 881 (expected conditional), last_login_datetime 72
A5: T01 Users_Messy_Audit | B5: 1008 | C5: 28 | D5: 2026-04-01 02:10:00 to 2026-09-15 19:47:00 | E5: user_id | F5: 1000 | G5: 8 | H5: 8 | I5: 966 | J5: 10 | K5: Contains 8 duplicate rows, 9 rows with single missing values, 1 malformed date
A6: SUP Users_1000 | B6: 1000 | C6: 16 | D6: 2026-04-01 02:00:41 to 2026-09-15 20:26:50 | E6: user_id | F6: 1000 | G6: 0 | H6: 0 | I6: 846 | J6: 1 | K6: Different people from T01 for the same IDs (DQ-014)
A7: SUP Sessions | B7: 7913 | C7: 12 | D7: 2026-04-02 20:14:28 to 2026-09-15 22:13:22 | E7: session_id | F7: 7913 | G7: 0 | H7: 0 | I7: 466 | J7: 1
A8: SUP Feature Events | B8: 35704 | C8: 13 | D8: 2026-04-02 20:14:31 to 2026-09-15 22:13:50 | E8: event_id | F8: 35704 | G8: 0 | H8: 0 | I8: 0 | J8: 0
A9: SUP Daily Activity | B9: 6667 | C9: 17 | D9: 2026-04-02 00:00:00 to 2026-09-15 00:00:00 | E9: user_id + activity_date | F9: 6667 | G9: 0 | H9: 0 | I9: 0 | J9: 0 | K9: Key is (user_id, activity_date); 0 duplicates on that pair
A10: SUP Task Activity | B10: 9846 | C10: 12 | D10: 2026-04-02 20:14:41 to 2026-09-15 21:51:41 | E10: activity_id | F10: 9846 | G10: 0 | H10: 0 | I10: 10494 | J10: 2 | K10: Nulls are structural (completion time, failure reason)
A11: SUP Milestones | B11: 4799 | C11: 6 | D11: 2026-04-02 08:18:00 to 2026-09-15 22:13:28 | E11: n/a (many per user by design) | F11: n/a | G11: n/a | H11: 0 | I11: 40 | J11: 1 | K11: Not unique by user (several milestones each)
A12: SUP Event audit sheet | B12: 35714 | C12: 13 | D12: 2026-04-02 20:14:31 to 2026-09-15 22:13:50 | E12: event_id | F12: 35704 | G12: 10 | H12: 10 | I12: 0 | J12: 0 | K12: 10 duplicate event_ids; case/space issues (DQ-022..024)
A15: Missing-cell share (formula)
A16: =A4 -> T01 Users_1000_Clean | B16: =I4/(B4*C4) -> 0.035296296
A17: =A5 -> T01 Users_Messy_Audit | B17: =I5/(B5*C5) -> 0.03422619
A18: =A6 -> SUP Users_1000 | B18: =I6/(B6*C6) -> 0.052875
A19: =A7 -> SUP Sessions | B19: =I7/(B7*C7) -> 0.0049075361
A20: =A8 -> SUP Feature Events | B20: =I8/(B8*C8) -> 0
A21: =A9 -> SUP Daily Activity | B21: =I9/(B9*C9) -> 0
A22: =A10 -> SUP Task Activity | B22: =I10/(B10*C10) -> 0.088817794
A23: =A11 -> SUP Milestones | B23: =I11/(B11*C11) -> 0.0013891783
A24: =A12 -> SUP Event audit sheet | B24: =I12/(B12*C12) -> 0
A27: Status / category distributions - T01 Users_1000_Clean (counts; share = formula)
A28: Field | B28: Value | C28: Count | D28: Share
A29: account_status | B29: Active | C29: 568 | D29: =C29/SUM($C$29:$C$32) -> 0.568
A30: account_status | B30: Inactive | C30: 283 | D30: =C30/SUM($C$29:$C$32) -> 0.283
A31: account_status | B31: Suspended | C31: 77 | D31: =C31/SUM($C$29:$C$32) -> 0.077
A32: account_status | B32: Pending Verification | C32: 72 | D32: =C32/SUM($C$29:$C$32) -> 0.072
A33: email_verification_status | B33: Verified | C33: 855 | D33: =C33/SUM($C$33:$C$34) -> 0.855
A34: email_verification_status | B34: Pending | C34: 145 | D34: =C34/SUM($C$33:$C$34) -> 0.145
A35: onboarding_status | B35: Completed | C35: 722 | D35: =C35/SUM($C$35:$C$37) -> 0.722
A36: onboarding_status | B36: Started | C36: 146 | D36: =C36/SUM($C$35:$C$37) -> 0.146
A37: onboarding_status | B37: Not Started | C37: 132 | D37: =C37/SUM($C$35:$C$37) -> 0.132
A38: acquisition_source | B38: Organic Search | C38: 244 | D38: =C38/SUM($C$38:$C$44) -> 0.244
A39: acquisition_source | B39: Direct | C39: 217 | D39: =C39/SUM($C$38:$C$44) -> 0.217
A40: acquisition_source | B40: Social Media | C40: 160 | D40: =C40/SUM($C$38:$C$44) -> 0.16
A41: acquisition_source | B41: Referral | C41: 119 | D41: =C41/SUM($C$38:$C$44) -> 0.119
A42: acquisition_source | B42: WhatsApp | C42: 103 | D42: =C42/SUM($C$38:$C$44) -> 0.103
A43: acquisition_source | B43: Other | C43: 102 | D43: =C43/SUM($C$38:$C$44) -> 0.102
A44: acquisition_source | B44: Telegram | C44: 55 | D44: =C44/SUM($C$38:$C$44) -> 0.055
...

Sheet 13 Column Profile
A1: J1 - Column-level profile (Users clean and audit)
A2: SIMULATED DATA - NOT ACTUAL VELOOP DATA. Status legend: Confirmed / Proposed / To Be Verified. No proposed item is claimed to exist in production.
A3: Dataset | B3: Column | C3: Stored Type | D3: Non-null | E3: Null | F3: Unique | G3: Min | H3: Max | I3: Top values (categorical)
A4: T01 Users_1000_Clean | B4: user_id | C4: str | D4: 1000 | E4: 0 | F4: 1000
A5: T01 Users_1000_Clean | B5: full_name | C5: str | D5: 1000 | E5: 0 | F5: 404
A6: T01 Users_1000_Clean | B6: email | C6: str | D6: 1000 | E6: 0 | F6: 1000
A7: T01 Users_1000_Clean | B7: age | C7: int64 | D7: 1000 | E7: 0 | F7: 21 | G7: 18 | H7: 38 | I7: 32: 64; 22: 60; 23: 57; 20: 56
A8: T01 Users_1000_Clean | B8: gender | C8: str | D8: 1000 | E8: 0 | F8: 3 | I8: Male: 343; Female: 331; Prefer not to say: 326
A9: T01 Users_1000_Clean | B9: state | C9: str | D9: 1000 | E9: 0 | F9: 17 | I9: Kerala: 129; Uttar Pradesh: 122; Bihar: 92; Odisha: 83
A10: T01 Users_1000_Clean | B10: city | C10: str | D10: 1000 | E10: 0 | F10: 29 | I10: Kochi: 129; Bhubaneswar: 83; Hyderabad: 63; Gaya: 49
A11: T01 Users_1000_Clean | B11: registration_datetime | C11: datetime64[us] | D11: 1000 | E11: 0 | F11: 999 | G11: 2026-04-01 02:10:00 | H11: 2026-09-15 19:47:00
A12: T01 Users_1000_Clean | B12: acquisition_source | C12: str | D12: 1000 | E12: 0 | F12: 7 | I12: Organic Search: 244; Direct: 217; Social Media: 160; Referral: 119
A13: T01 Users_1000_Clean | B13: referral_source_detail | C13: str | D13: 119 | E13: 881 | F13: 1 | I13: Friend/Family: 119
A14: T01 Users_1000_Clean | B14: primary_device | C14: str | D14: 1000 | E14: 0 | F14: 4 | I14: Android: 659; Windows: 155; iOS: 140; macOS: 46
A15: T01 Users_1000_Clean | B15: platform | C15: str | D15: 1000 | E15: 0 | F15: 1 | I15: Web: 1000
A16: T01 Users_1000_Clean | B16: account_status | C16: str | D16: 1000 | E16: 0 | F16: 4 | I16: Active: 568; Inactive: 283; Suspended: 77; Pending Verification: 72
A17: T01 Users_1000_Clean | B17: email_verification_status | C17: str | D17: 1000 | E17: 0 | F17: 2 | I17: Verified: 855; Pending: 145
A18: T01 Users_1000_Clean | B18: onboarding_status | C18: str | D18: 1000 | E18: 0 | F18: 3 | I18: Completed: 722; Started: 146; Not Started: 132
A19: T01 Users_1000_Clean | B19: last_login_datetime | C19: datetime64[us] | D19: 928 | E19: 72 | F19: 899 | G19: 2026-04-15 02:51:00 | H19: 2026-09-17 10:08:00
A20: T01 Users_1000_Clean | B20: lifetime_sessions | C20: int64 | D20: 1000 | E20: 0 | F20: 58 | G20: 0 | H20: 81
A21: T01 Users_1000_Clean | B21: active_days | C21: int64 | D21: 1000 | E21: 0 | F21: 33 | G21: 0 | H21: 32 | I21: 0: 121; 6: 74; 4: 68; 7: 67
A22: T01 Users_1000_Clean | B22: xp_balance | C22: int64 | D22: 1000 | E22: 0 | F22: 450 | G22: 5 | H22: 1156
A23: T01 Users_1000_Clean | B23: referral_code | C23: str | D23: 1000 | E23: 0 | F23: 1000
A24: T01 Users_1000_Clean | B24: days_since_registration | C24: float64 | D24: 1000 | E24: 0 | F24: 754 | G24: -0.8 | H24: 166.9
A25: T01 Users_1000_Clean | B25: is_active_7d | C25: str | D25: 1000 | E25: 0 | F25: 2 | I25: No: 922; Yes: 78
A26: T01 Users_1000_Clean | B26: is_active_30d | C26: str | D26: 1000 | E26: 0 | F26: 2 | I26: No: 675; Yes: 325
A27: T01 Users_1000_Clean | B27: consent_status | C27: str | D27: 1000 | E27: 0 | F27: 2 | I27: Accepted: 923; Pending: 77
A28: T01 Users_1000_Clean | B28: marketing_opt_in | C28: str | D28: 1000 | E28: 0 | F28: 2 | I28: No: 558; Yes: 442
A29: T01 Users_1000_Clean | B29: account_created_via | C29: str | D29: 1000 | E29: 0 | F29: 2 | I29: Web Registration: 661; Google Sign-In: 339
A30: T01 Users_1000_Clean | B30: country | C30: str | D30: 1000 | E30: 0 | F30: 1 | I30: India: 1000
A31: T01 Users_Messy_Audit | B31: user_id | C31: str | D31: 1008 | E31: 0 | F31: 1000
A32: T01 Users_Messy_Audit | B32: full_name | C32: str | D32: 1008 | E32: 0 | F32: 404
A33: T01 Users_Messy_Audit | B33: email | C33: str | D33: 1008 | E33: 0 | F33: 1000
A34: T01 Users_Messy_Audit | B34: age | C34: str | D34: 1007 | E34: 1 | F34: 21 | G34: 18.0 | H34: 38.0 | I34: 32: 65; 22: 60; 23: 57; 20: 56
A35: T01 Users_Messy_Audit | B35: gender | C35: str | D35: 1007 | E35: 1 | F35: 3 | I35: Male: 345; Female: 332; Prefer not to say: 330
A36: T01 Users_Messy_Audit | B36: state | C36: str | D36: 1008 | E36: 0 | F36: 17 | I36: Kerala: 129; Uttar Pradesh: 124; Bihar: 93; Odisha: 83
A37: T01 Users_Messy_Audit | B37: city | C37: str | D37: 1007 | E37: 1 | F37: 29 | I37: Kochi: 129; Bhubaneswar: 82; Hyderabad: 63; Gaya: 49
A38: T01 Users_Messy_Audit | B38: registration_datetime | C38: str | D38: 1007 | E38: 1 | F38: 998
A39: T01 Users_Messy_Audit | B39: acquisition_source | C39: str | D39: 1007 | E39: 1 | F39: 7 | I39: Organic Search: 245; Direct: 216; Social Media: 160; Referral: 123
A40: T01 Users_Messy_Audit | B40: referral_source_detail | C40: str | D40: 123 | E40: 885 | F40: 1 | I40: Friend/Family: 123
...

Sheet 14 Relationships (J2)
A1: J2 - Relationship tests
A2: SIMULATED DATA - NOT ACTUAL VELOOP DATA. Status legend: Confirmed / Proposed / To Be Verified. No proposed item is claimed to exist in production.
A3: Test | B3: Result | C3: Evidence | D3: Note
A4: T01 Users.user_id unique and non-null | B4: Pass | C4: 1,000 unique of 1,000 rows; 0 nulls | D4: Users_1000_Clean
A5: T01 Users.email unique | B5: Pass | C5: 1,000 unique | D5: Users_1000_Clean
A6: T01 Users.referral_code unique | B6: Pass | C6: 1,000 unique; format VL+6 digits for all | D6: Users_1000_Clean
A7: T01 Users.user_id -> Task Activity.user_id | B7: Not testable | C7: Task Activity sheet not supplied in Task 01 file (S005, A003) | D7: -
A8: T01 Users.user_id -> Rewards.user_id | B8: Not testable | C8: Rewards sheet not supplied | D8: -
A9: T01 Users.user_id -> Wallet.user_id | B9: Not testable | C9: Wallet sheet not supplied | D9: -
A10: T01 Users.user_id -> Withdrawals.user_id | B10: Not testable | C10: Withdrawals sheet not supplied | D10: -
A11: T01 Users.user_id -> Referrals | B11: Not testable | C11: Referrals sheet not supplied; Users holds only a code and "Friend/Family" label (DQ-021) | D11: -
A12: T01 Users_Messy_Audit.user_id -> Users_1000_Clean.user_id | B12: Pass | C12: All 1,000 audit IDs exist in clean; 0 audit IDs missing from clean; 8 repeated rows | D12: -
A13: SUP Users -> Sessions.user_id | B13: Pass | C13: 0 orphan sessions of 7,913
A14: SUP Users -> Feature Events.user_id | B14: Pass | C14: 0 orphan events of 35,704
A15: SUP Users -> Task Activity.user_id | B15: Pass | C15: 0 orphan attempts of 9,846
A16: SUP Users -> Daily Activity.user_id | B16: Pass | C16: 0 orphan rows
A17: SUP Users -> Milestones.user_id | B17: Pass | C17: 0 orphan rows
A18: SUP Sessions.session_id -> Events / Tasks | B18: Pass | C18: 0 orphan session references
A19: SUP Users without any session or task | B19: Observation | C19: 16 of 1,000 users have no sessions and no tasks
A20: T01 Users vs SUP Users on user_id | B20: FAIL - do not join | C20: 1000 IDs overlap but 0 emails, 0 names, 0 registration times and 0 referral codes match; 429 statuses match (chance level). The files describe different people (DQ-014)

Sheet 15 KPI Test (J3)
A1: J3 - Can the KPIs actually be calculated from the supplied structure? (all results SIMULATED)
A2: SIMULATED DATA - NOT ACTUAL VELOOP DATA. Status legend: Confirmed / Proposed / To Be Verified. No proposed item is claimed to exist in production.
A3: KPI | B3: Calculable? | C3: Result or Reason (simulated wording) | D3: Additional Data Required
A4: K-U01 New registrations | B4: Yes | C4: In the simulated dataset (T01 clean), 1,000 users registered between 01 Apr and 15 Sep 2026; by month: 2026-04: 174, 2026-05: 179, 2026-06: 166, 2026-07: 198, 2026-08: 192, 2026-09: 91 | D4: -
